Workbook

Sheet Parametros
A1: Parametro | B1: Valor | C1: Fuente / Nota
A2: SMLV 2026 | B2: 1750905 | C2: Salario minimo legal vigente (valor base de la planilla original)
A3: Auxilio de Transporte 2026 | B3: 249095 | C3: Valor mensual (aplica solo si IBC <= 2 SMLV)
A4: Tope Aux. Transporte (2 SMLV) | B4: =B2*2 -> 3501810 | C4: Decreto anual - Codigo Sustantivo del Trabajo Art. 7 Ley 15/1959
A5: % Aporte Salud Trabajador | B5: 0.04 | C5: Ley 100 de 1993, Art. 204
A6: % Aporte Pension Trabajador | B6: 0.04 | C6: Ley 100 de 1993, Art. 20
A7: % Aporte Salud Empleador | B7: 0.085 | C7: Ley 100 de 1993, Art. 204
A8: % Aporte Pension Empleador | B8: 0.12 | C8: Ley 100 de 1993, Art. 20
A9: % Aporte CCF Empleador | B9: 0.04 | C9: Ley 21 de 1982
A10: % Provision Cesantias (mensual) | B10: =1/12 -> 0.083333333 | C10: Un salario mensual (base+aux.transp.) por año trabajado, Ley 50 de 1990
A11: % Intereses sobre Cesantias | B11: 0.12 | C11: 12% anual sobre cesantias causadas, Ley 52 de 1975
A12: % Provision Prima (mensual) | B12: =1/12 -> 0.083333333 | C12: Un salario mensual (base+aux.transp.) por año, pagadero semestral, CST Art. 306
A13: % Provision Vacaciones | B13: 0.0417 | C13: 15 dias habiles / 360 sobre el salario base, CST Art. 186

Sheet Nomina
A1: ID EMPLEADO | B1: PRIMER APELLIDO | C1: PRIMER NOMBRE | D1: SEXO | E1: FECHA NACIMIENTO | F1: ESTADO CIVIL | G1: DEPARTAMENTO | H1: MUNICIPIO | I1: OCUPACION | J1: FECHA INGRESO | K1: FECHA RETIRO | L1: EPS | M1: AFP | N1: ARL | O1: CCF | P1: NIVEL RIESGO | Q1: IBC | R1: AUX DE TRANSPORTE | S1: DESCUENTO TRABAJADOR EPS | T1: DESCUENTO TRABAJADOR PENSION | U1: CESANTIAS | V1: INTERESES DE CESANTIAS | W1: PROVISION PRIMA | X1: PROVISION VACACIONES | Y1: APORTE SALUD EMPLEADOR 8,5% | Z1: APORTE PENSION EMPLEADOR 12% | AA1: APORTE EMPLEADOR CCF | AB1: APORTE EMPLEADOR ARL
A2: EMP-001 | B2: Ortiz | C2: Oscar | D2: M | E2: 33486 | F2: Soltero | G2: Bogotá D.C | H2: Bogotá | I2: AUXILIAR DE BODEGA | J2: 46082 | L2: SALUD TOTAL | M2: PORVENIR S.A. | N2: ARL SURA | O2: COLSUBSIDIO | P2: 0.0435 | Q2: 1750905 | R2: =IF(Q2<=Parametros!$B$4,Parametros!$B$3,0) -> 249095 | S2: =Q2*Parametros!$B$5 -> 70036.2 | T2: =Q2*Parametros!$B$6 -> 70036.2 | U2: =(Q2+R2)*Parametros!$B$10 -> 166666.67 | V2: =U2*Parametros!$B$11 -> 20000 | W2: =(Q2+R2)*Parametros!$B$12 -> 166666.67 | X2: =Q2*Parametros!$B$13 -> 73012.739 | Y2: =Q2*Parametros!$B$7 -> 148826.92 | Z2: =Q2*Parametros!$B$8 -> 210108.6 | AA2: =Q2*Parametros!$B$9 -> 70036.2 | AB2: =Q2*P2 -> 76164.367
A3: EMP-002 | B3: Alvarez | C3: Jorge | D3: M | E3: 28106 | F3: Soltero | G3: Bogotá D.C | H3: Bogotá | I3: ANALISTA DE INVENTARIOS | J3: 44838 | L3: SALUD TOTAL | M3: PORVENIR S.A. | N3: ARL SURA | O3: COLSUBSIDIO | P3: 0.00522 | Q3: 1750905 | R3: =IF(Q3<=Parametros!$B$4,Parametros!$B$3,0) -> 249095 | S3: =Q3*Parametros!$B$5 -> 70036.2 | T3: =Q3*Parametros!$B$6 -> 70036.2 | U3: =(Q3+R3)*Parametros!$B$10 -> 166666.67 | V3: =U3*Parametros!$B$11 -> 20000 | W3: =(Q3+R3)*Parametros!$B$12 -> 166666.67 | X3: =Q3*Parametros!$B$13 -> 73012.739 | Y3: =Q3*Parametros!$B$7 -> 148826.92 | Z3: =Q3*Parametros!$B$8 -> 210108.6 | AA3: =Q3*Parametros!$B$9 -> 70036.2 | AB3: =Q3*P3 -> 9139.7241
A4: EMP-003 | B4: Ramirez | C4: Sergio | D4: M | E4: 32609 | F4: Soltero | G4: Bogotá D.C | H4: Bogotá | I4: AUXILIAR DE BODEGA | J4: 44958 | L4: SURA EPS | M4: PROTECCION | N4: ARL SURA | O4: COLSUBSIDIO | P4: 0.0435 | Q4: 1750905 | R4: =IF(Q4<=Parametros!$B$4,Parametros!$B$3,0) -> 249095 | S4: =Q4*Parametros!$B$5 -> 70036.2 | T4: =Q4*Parametros!$B$6 -> 70036.2 | U4: =(Q4+R4)*Parametros!$B$10 -> 166666.67 | V4: =U4*Parametros!$B$11 -> 20000 | W4: =(Q4+R4)*Parametros!$B$12 -> 166666.67 | X4: =Q4*Parametros!$B$13 -> 73012.739 | Y4: =Q4*Parametros!$B$7 -> 148826.92 | Z4: =Q4*Parametros!$B$8 -> 210108.6 | AA4: =Q4*Parametros!$B$9 -> 70036.2 | AB4: =Q4*P4 -> 76164.367
A5: EMP-004 | B5: Moreno | C5: Johana | D5: F | E5: 32736 | F5: Soltero | G5: Bogotá D.C | H5: Bogotá | I5: AUXILIAR DE BODEGA | J5: 45597 | L5: COMPENSAR EPS | M5: COLPENSIONES | N5: ARL SURA | O5: COLSUBSIDIO | P5: 0.0435 | Q5: 1750905 | R5: =IF(Q5<=Parametros!$B$4,Parametros!$B$3,0) -> 249095 | S5: =Q5*Parametros!$B$5 -> 70036.2 | T5: =Q5*Parametros!$B$6 -> 70036.2 | U5: =(Q5+R5)*Parametros!$B$10 -> 166666.67 | V5: =U5*Parametros!$B$11 -> 20000 | W5: =(Q5+R5)*Parametros!$B$12 -> 166666.67 | X5: =Q5*Parametros!$B$13 -> 73012.739 | Y5: =Q5*Parametros!$B$7 -> 148826.92 | Z5: =Q5*Parametros!$B$8 -> 210108.6 | AA5: =Q5*Parametros!$B$9 -> 70036.2 | AB5: =Q5*P5 -> 76164.367
A6: EMP-005 | B6: Mendoza | C6: Laura | D6: F | E6: 34029 | F6: Soltero | G6: Bogotá D.C | H6: Bogotá | I6: AUXILIAR DE BODEGA | J6: 45726 | L6: COMPENSAR EPS | M6: PORVENIR S.A. | N6: ARL SURA | O6: COMPENSAR | P6: 0.0435 | Q6: 1750905 | R6: =IF(Q6<=Parametros!$B$4,Parametros!$B$3,0) -> 249095 | S6: =Q6*Parametros!$B$5 -> 70036.2 | T6: =Q6*Parametros!$B$6 -> 70036.2 | U6: =(Q6+R6)*Parametros!$B$10 -> 166666.67 | V6: =U6*Parametros!$B$11 -> 20000 | W6: =(Q6+R6)*Parametros!$B$12 -> 166666.67 | X6: =Q6*Parametros!$B$13 -> 73012.739 | Y6: =Q6*Parametros!$B$7 -> 148826.92 | Z6: =Q6*Parametros!$B$8 -> 210108.6 | AA6: =Q6*Parametros!$B$9 -> 70036.2 | AB6: =Q6*P6 -> 76164.367
A7: EMP-006 | B7: Mendoza | C7: Juan | D7: M | E7: 31492 | F7: Soltero | G7: Bogotá D.C | H7: Bogotá | I7: AUXILIAR DE BODEGA | J7: 45866 | L7: SANITAS | M7: PROTECCION | N7: ARL SURA | O7: COLSUBSIDIO | P7: 0.0435 | Q7: 1750905 | R7: =IF(Q7<=Parametros!$B$4,Parametros!$B$3,0) -> 249095 | S7: =Q7*Parametros!$B$5 -> 70036.2 | T7: =Q7*Parametros!$B$6 -> 70036.2 | U7: =(Q7+R7)*Parametros!$B$10 -> 166666.67 | V7: =U7*Parametros!$B$11 -> 20000 | W7: =(Q7+R7)*Parametros!$B$12 -> 166666.67 | X7: =Q7*Parametros!$B$13 -> 73012.739 | Y7: =Q7*Parametros!$B$7 -> 148826.92 | Z7: =Q7*Parametros!$B$8 -> 210108.6 | AA7: =Q7*Parametros!$B$9 -> 70036.2 | AB7: =Q7*P7 -> 76164.367
A8: EMP-007 | B8: Cardenas | C8: Gloria | D8: F | E8: 28718 | F8: Soltero | G8: Bogotá D.C | H8: Bogotá | I8: AUXILIAR DE BODEGA | J8: 45058 | L8: COMPENSAR EPS | M8: PROTECCION | N8: ARL SURA | O8: COLSUBSIDIO | P8: 0.0435 | Q8: 1750905 | R8: =IF(Q8<=Parametros!$B$4,Parametros!$B$3,0) -> 249095 | S8: =Q8*Parametros!$B$5 -> 70036.2 | T8: =Q8*Parametros!$B$6 -> 70036.2 | U8: =(Q8+R8)*Parametros!$B$10 -> 166666.67 | V8: =U8*Parametros!$B$11 -> 20000 | W8: =(Q8+R8)*Parametros!$B$12 -> 166666.67 | X8: =Q8*Parametros!$B$13 -> 73012.739 | Y8: =Q8*Parametros!$B$7 -> 148826.92 | Z8: =Q8*Parametros!$B$8 -> 210108.6 | AA8: =Q8*Parametros!$B$9 -> 70036.2 | AB8: =Q8*P8 -> 76164.367
A9: EMP-008 | B9: Hernandez | C9: Alejandro | D9: M | E9: 31878 | F9: Soltero | G9: Bogotá D.C | H9: Bogotá | I9: ASESOR COMERCIAL | J9: 44256 | L9: COMPENSAR EPS | M9: PORVENIR S.A. | N9: ARL SURA | O9: COLSUBSIDIO | P9: 0.00522 | Q9: 2000000 | R9: =IF(Q9<=Parametros!$B$4,Parametros!$B$3,0) -> 249095 | S9: =Q9*Parametros!$B$5 -> 80000 | T9: =Q9*Parametros!$B$6 -> 80000 | U9: =(Q9+R9)*Parametros!$B$10 -> 187424.58 | V9: =U9*Parametros!$B$11 -> 22490.95 | W9: =(Q9+R9)*Parametros!$B$12 -> 187424.58 | X9: =Q9*Parametros!$B$13 -> 83400 | Y9: =Q9*Parametros!$B$7 -> 170000 | Z9: =Q9*Parametros!$B$8 -> 240000 | AA9: =Q9*Parametros!$B$9 -> 80000 | AB9: =Q9*P9 -> 10440
A10: EMP-009 | B10: Diaz | C10: Luis | D10: M | E10: 28492 | F10: Soltero | G10: Bogotá D.C | H10: Bogotá | I10: ASESOR COMERCIAL | J10: 46167 | K10: 46174 | L10: FAMISANAR | M10: COLFONDOS | N10: ARL SURA | O10: COLSUBSIDIO | P10: 0.00522 | Q10: 2000000 | R10: =IF(Q10<=Parametros!$B$4,Parametros!$B$3,0) -> 249095 | S10: =Q10*Parametros!$B$5 -> 80000 | T10: =Q10*Parametros!$B$6 -> 80000 | U10: =(Q10+R10)*Parametros!$B$10 -> 187424.58 | V10: =U10*Parametros!$B$11 -> 22490.95 | W10: =(Q10+R10)*Parametros!$B$12 -> 187424.58 | X10: =Q10*Parametros!$B$13 -> 83400 | Y10: =Q10*Parametros!$B$7 -> 170000 | Z10: =Q10*Parametros!$B$8 -> 240000 | AA10: =Q10*Parametros!$B$9 -> 80000 | AB10: =Q10*P10 -> 10440
A11: EMP-010 | B11: Cruz | C11: Catalina | D11: F | E11: 32384 | F11: Soltero | G11: Bogotá D.C | H11: Bogotá | I11: ASESOR COMERCIAL | J11: 46014 | L11: FAMISANAR | M11: PORVENIR S.A. | N11: ARL SURA | O11: COLSUBSIDIO | P11: 0.00522 | Q11: 2000000 | R11: =IF(Q11<=Parametros!$B$4,Parametros!$B$3,0) -> 249095 | S11: =Q11*Parametros!$B$5 -> 80000 | T11: =Q11*Parametros!$B$6 -> 80000 | U11: =(Q11+R11)*Parametros!$B$10 -> 187424.58 | V11: =U11*Parametros!$B$11 -> 22490.95 | W11: =(Q11+R11)*Parametros!$B$12 -> 187424.58 | X11: =Q11*Parametros!$B$13 -> 83400 | Y11: =Q11*Parametros!$B$7 -> 170000 | Z11: =Q11*Parametros!$B$8 -> 240000 | AA11: =Q11*Parametros!$B$9 -> 80000 | AB11: =Q11*P11 -> 10440
A12: EMP-011 | B12: Mendoza | C12: David | D12: M | E12: 26527 | F12: Soltero | G12: Bogotá D.C | H12: Bogotá | I12: ASESOR COMERCIAL | J12: 45413 | L12: COMPENSAR EPS | M12: PORVENIR S.A. | N12: ARL SURA | O12: COLSUBSIDIO | P12: 0.00522 | Q12: 2000000 | R12: =IF(Q12<=Parametros!$B$4,Parametros!$B$3,0) -> 249095 | S12: =Q12*Parametros!$B$5 -> 80000 | T12: =Q12*Parametros!$B$6 -> 80000 | U12: =(Q12+R12)*Parametros!$B$10 -> 187424.58 | V12: =U12*Parametros!$B$11 -> 22490.95 | W12: =(Q12+R12)*Parametros!$B$12 -> 187424.58 | X12: =Q12*Parametros!$B$13 -> 83400 | Y12: =Q12*Parametros!$B$7 -> 170000 | Z12: =Q12*Parametros!$B$8 -> 240000 | AA12: =Q12*Parametros!$B$9 -> 80000 | AB12: =Q12*P12 -> 10440
A13: EMP-012 | B13: Duque | C13: Andres | D13: M | E13: 28878 | F13: Soltero | G13: Cundinamarca | H13: SOACHA | I13: ASESOR COMERCIAL | J13: 45383 | L13: SANITAS | M13: COLFONDOS | N13: ARL SURA | O13: COLSUBSIDIO | P13: 0.00522 | Q13: 2000000 | R13: =IF(Q13<=Parametros!$B$4,Parametros!$B$3,0) -> 249095 | S13: =Q13*Parametros!$B$5 -> 80000 | T13: =Q13*Parametros!$B$6 -> 80000 | U13: =(Q13+R13)*Parametros!$B$10 -> 187424.58 | V13: =U13*Parametros!$B$11 -> 22490.95 | W13: =(Q13+R13)*Parametros!$B$12 -> 187424.58 | X13: =Q13*Parametros!$B$13 -> 83400 | Y13: =Q13*Parametros!$B$7 -> 170000 | Z13: =Q13*Parametros!$B$8 -> 240000 | AA13: =Q13*Parametros!$B$9 -> 80000 | AB13: =Q13*P13 -> 10440
A14: EMP-013 | B14: Jimenez | C14: Lorena | D14: F | E14: 28595 | F14: Soltero | G14: Bogotá D.C | H14: Bogotá | I14: CONDUCTOR | J14: 45932 | L14: SANITAS | M14: PROTECCION | N14: ARL SURA | O14: COLSUBSIDIO | P14: 0.0696 | Q14: 1900000 | R14: =IF(Q14<=Parametros!$B$4,Parametros!$B$3,0) -> 249095 | S14: =Q14*Parametros!$B$5 -> 76000 | T14: =Q14*Parametros!$B$6 -> 76000 | U14: =(Q14+R14)*Parametros!$B$10 -> 179091.25 | V14: =U14*Parametros!$B$11 -> 21490.95 | W14: =(Q14+R14)*Parametros!$B$12 -> 179091.25 | X14: =Q14*Parametros!$B$13 -> 79230 | Y14: =Q14*Parametros!$B$7 -> 161500 | Z14: =Q14*Parametros!$B$8 -> 228000 | AA14: =Q14*Parametros!$B$9 -> 76000 | AB14: =Q14*P14 -> 132240
A15: EMP-014 | B15: Ramirez | C15: Mauricio | D15: M | E15: 27760 | F15: Soltero | G15: Bogotá D.C | H15: Bogotá | I15: CONDUCTOR | J15: 45993 | L15: FAMISANAR | M15: PORVENIR S.A. | N15: ARL SURA | O15: COLSUBSIDIO | P15: 0.0696 | Q15: 1900000 | R15: =IF(Q15<=Parametros!$B$4,Parametros!$B$3,0) -> 249095 | S15: =Q15*Parametros!$B$5 -> 76000 | T15: =Q15*Parametros!$B$6 -> 76000 | U15: =(Q15+R15)*Parametros!$B$10 -> 179091.25 | V15: =U15*Parametros!$B$11 -> 21490.95 | W15: =(Q15+R15)*Parametros!$B$12 -> 179091.25 | X15: =Q15*Parametros!$B$13 -> 79230 | Y15: =Q15*Parametros!$B$7 -> 161500 | Z15: =Q15*Parametros!$B$8 -> 228000 | AA15: =Q15*Parametros!$B$9 -> 76000 | AB15: =Q15*P15 -> 132240
A16: EMP-015 | B16: Rivera | C16: Diego | D16: M | E16: 30068 | F16: Soltero | G16: Bogotá D.C | H16: Bogotá | I16: AUXILIAR DE BODEGA | J16: 43826 | L16: SANITAS | M16: COLPENSIONES | N16: ARL SURA | O16: COLSUBSIDIO | P16: 0.0435 | Q16: 1750905 | R16: =IF(Q16<=Parametros!$B$4,Parametros!$B$3,0) -> 249095 | S16: =Q16*Parametros!$B$5 -> 70036.2 | T16: =Q16*Parametros!$B$6 -> 70036.2 | U16: =(Q16+R16)*Parametros!$B$10 -> 166666.67 | V16: =U16*Parametros!$B$11 -> 20000 | W16: =(Q16+R16)*Parametros!$B$12 -> 166666.67 | X16: =Q16*Parametros!$B$13 -> 73012.739 | Y16: =Q16*Parametros!$B$7 -> 148826.92 | Z16: =Q16*Parametros!$B$8 -> 210108.6 | AA16: =Q16*Parametros!$B$9 -> 70036.2 | AB16: =Q16*P16 -> 76164.367
A17: EMP-016 | B17: Duque | C17: Andres | D17: M | E17: 27743 | F17: Soltero | G17: Bogotá D.C | H17: Bogotá | I17: CONDUCTOR | J17: 46217 | L17: SALUD TOTAL | M17: PROTECCION | N17: ARL SURA | O17: COLSUBSIDIO | P17: 0.0696 | Q17: 1900000 | R17: =IF(Q17<=Parametros!$B$4,Parametros!$B$3,0) -> 249095 | S17: =Q17*Parametros!$B$5 -> 76000 | T17: =Q17*Parametros!$B$6 -> 76000 | U17: =(Q17+R17)*Parametros!$B$10 -> 179091.25 | V17: =U17*Parametros!$B$11 -> 21490.95 | W17: =(Q17+R17)*Parametros!$B$12 -> 179091.25 | X17: =Q17*Parametros!$B$13 -> 79230 | Y17: =Q17*Parametros!$B$7 -> 161500 | Z17: =Q17*Parametros!$B$8 -> 228000 | AA17: =Q17*Parametros!$B$9 -> 76000 | AB17: =Q17*P17 -> 132240
A18: EMP-017 | B18: Jimenez | C18: Juan | D18: M | E18: 28024 | F18: Soltero | G18: Bogotá D.C | H18: Bogotá | I18: AUXILIAR DE BODEGA | J18: 46056 | L18: FAMISANAR | M18: PROTECCION | N18: ARL SURA | O18: COMPENSAR | P18: 0.0435 | Q18: 1750905 | R18: =IF(Q18<=Parametros!$B$4,Parametros!$B$3,0) -> 249095 | S18: =Q18*Parametros!$B$5 -> 70036.2 | T18: =Q18*Parametros!$B$6 -> 70036.2 | U18: =(Q18+R18)*Parametros!$B$10 -> 166666.67 | V18: =U18*Parametros!$B$11 -> 20000 | W18: =(Q18+R18)*Parametros!$B$12 -> 166666.67 | X18: =Q18*Parametros!$B$13 -> 73012.739 | Y18: =Q18*Parametros!$B$7 -> 148826.92 | Z18: =Q18*Parametros!$B$8 -> 210108.6 | AA18: =Q18*Parametros!$B$9 -> 70036.2 | AB18: =Q18*P18 -> 76164.367
A19: EMP-018 | B19: Silva | C19: Monica | D19: F | E19: 30377 | F19: Soltero | G19: Bogotá D.C | H19: Bogotá | I19: ASESOR COMERCIAL | J19: 46029 | L19: SANITAS | M19: PROTECCION | N19: ARL SURA | O19: COLSUBSIDIO | P19: 0.00522 | Q19: 2000000 | R19: =IF(Q19<=Parametros!$B$4,Parametros!$B$3,0) -> 249095 | S19: =Q19*Parametros!$B$5 -> 80000 | T19: =Q19*Parametros!$B$6 -> 80000 | U19: =(Q19+R19)*Parametros!$B$10 -> 187424.58 | V19: =U19*Parametros!$B$11 -> 22490.95 | W19: =(Q19+R19)*Parametros!$B$12 -> 187424.58 | X19: =Q19*Parametros!$B$13 -> 83400 | Y19: =Q19*Parametros!$B$7 -> 170000 | Z19: =Q19*Parametros!$B$8 -> 240000 | AA19: =Q19*Parametros!$B$9 -> 80000 | AB19: =Q19*P19 -> 10440
A20: EMP-019 | B20: Castillo | C20: Julian | D20: M | E20: 30016 | F20: Soltero | G20: Bogotá D.C | H20: Bogotá | I20: CONDUCTOR | J20: 46113 | L20: SALUD TOTAL | M20: PROTECCION | N20: ARL SURA | O20: COLSUBSIDIO | P20: 0.0696 | Q20: 1900000 | R20: =IF(Q20<=Parametros!$B$4,Parametros!$B$3,0) -> 249095 | S20: =Q20*Parametros!$B$5 -> 76000 | T20: =Q20*Parametros!$B$6 -> 76000 | U20: =(Q20+R20)*Parametros!$B$10 -> 179091.25 | V20: =U20*Parametros!$B$11 -> 21490.95 | W20: =(Q20+R20)*Parametros!$B$12 -> 179091.25 | X20: =Q20*Parametros!$B$13 -> 79230 | Y20: =Q20*Parametros!$B$7 -> 161500 | Z20: =Q20*Parametros!$B$8 -> 228000 | AA20: =Q20*Parametros!$B$9 -> 76000 | AB20: =Q20*P20 -> 132240
A21: EMP-020 | B21: Nunez | C21: Juan | D21: M | E21: 26594 | F21: Soltero | G21: Bogotá D.C | H21: Bogotá | I21: AUXILIAR ADMINISTRATIVO | J21: 45383 | L21: FAMISANAR | M21: COLPENSIONES | N21: ARL SURA | O21: COLSUBSIDIO | P21: 0.00522 | Q21: 1750905 | R21: =IF(Q21<=Parametros!$B$4,Parametros!$B$3,0) -> 249095 | S21: =Q21*Parametros!$B$5 -> 70036.2 | T21: =Q21*Parametros!$B$6 -> 70036.2 | U21: =(Q21+R21)*Parametros!$B$10 -> 166666.67 | V21: =U21*Parametros!$B$11 -> 20000 | W21: =(Q21+R21)*Parametros!$B$12 -> 166666.67 | X21: =Q21*Parametros!$B$13 -> 73012.739 | Y21: =Q21*Parametros!$B$7 -> 148826.92 | Z21: =Q21*Parametros!$B$8 -> 210108.6 | AA21: =Q21*Parametros!$B$9 -> 70036.2 | AB21: =Q21*P21 -> 9139.7241
A22: EMP-021 | B22: Rojas | C22: Santiago | D22: M | E22: 29940 | F22: Soltero | G22: Bogotá D.C | H22: Bogotá | I22: CONDUCTOR | J22: 46204 | L22: SANITAS | M22: PORVENIR S.A. | N22: ARL SURA | O22: COLSUBSIDIO | P22: 0.0696 | Q22: 1900000 | R22: =IF(Q22<=Parametros!$B$4,Parametros!$B$3,0) -> 249095 | S22: =Q22*Parametros!$B$5 -> 76000 | T22: =Q22*Parametros!$B$6 -> 76000 | U22: =(Q22+R22)*Parametros!$B$10 -> 179091.25 | V22: =U22*Parametros!$B$11 -> 21490.95 | W22: =(Q22+R22)*Parametros!$B$12 -> 179091.25 | X22: =Q22*Parametros!$B$13 -> 79230 | Y22: =Q22*Parametros!$B$7 -> 161500 | Z22: =Q22*Parametros!$B$8 -> 228000 | AA22: =Q22*Parametros!$B$9 -> 76000 | AB22: =Q22*P22 -> 132240
... A42: EMP-041 | B42: Herrera | C42: Leonardo | D42: M | E42: 26660 | F42: Soltero | G42: Bogotá D.C | H42: Bogotá | I42: AUXILIAR CONTABLE | J42: 46177 | L42: SALUD TOTAL | M42: PORVENIR S.A. | N42: ARL SURA | O42: COLSUBSIDIO | P42: 0.00522 | Q42: 1750905 | R42: =IF(Q42<=Parametros!$B$4,Parametros!$B$3,0) -> 249095 | S42: =Q42*Parametros!$B$5 -> 70036.2 | T42: =Q42*Parametros!$B$6 -> 70036.2 | U42: =(Q42+R42)*Parametros!$B$10 -> 166666.67 | V42: =U42*Parametros!$B$11 -> 20000 | W42: =(Q42+R42)*Parametros!$B$12 -> 166666.67 | X42: =Q42*Parametros!$B$13 -> 73012.739 | Y42: =Q42*Parametros!$B$7 -> 148826.92 | Z42: =Q42*Parametros!$B$8 -> 210108.6 | AA42: =Q42*Parametros!$B$9 -> 70036.2 | AB42: =Q42*P42 -> 9139.7241
A43: EMP-042 | B43: Ramirez | C43: Jorge | D43: M | E43: 27095 | F43: Soltero | G43: Bogotá D.C | H43: Bogotá | I43: AUXILIAR DE BODEGA | J43: 46097 | K43: 46143 | L43: SANITAS | M43: COLPENSIONES | N43: ARL SURA | O43: COLSUBSIDIO | P43: 0.0435 | Q43: 1750905 | R43: =IF(Q43<=Parametros!$B$4,Parametros!$B$3,0) -> 249095 | S43: =Q43*Parametros!$B$5 -> 70036.2 | T43: =Q43*Parametros!$B$6 -> 70036.2 | U43: =(Q43+R43)*Parametros!$B$10 -> 166666.67 | V43: =U43*Parametros!$B$11 -> 20000 | W43: =(Q43+R43)*Parametros!$B$12 -> 166666.67 | X43: =Q43*Parametros!$B$13 -> 73012.739 | Y43: =Q43*Parametros!$B$7 -> 148826.92 | Z43: =Q43*Parametros!$B$8 -> 210108.6 | AA43: =Q43*Parametros!$B$9 -> 70036.2 | AB43: =Q43*P43 -> 76164.367
A44: EMP-043 | B44: Bautista | C44: Ricardo | D44: M | E44: 25900 | F44: Soltero | G44: Cundinamarca | H44: MOSQUERA | I44: CONDUCTOR | J44: 45717 | L44: FAMISANAR | M44: PORVENIR S.A. | N44: ARL SURA | O44: COLSUBSIDIO | P44: 0.0696 | Q44: 1900000 | R44: =IF(Q44<=Parametros!$B$4,Parametros!$B$3,0) -> 249095 | S44: =Q44*Parametros!$B$5 -> 76000 | T44: =Q44*Parametros!$B$6 -> 76000 | U44: =(Q44+R44)*Parametros!$B$10 -> 179091.25 | V44: =U44*Parametros!$B$11 -> 21490.95 | W44: =(Q44+R44)*Parametros!$B$12 -> 179091.25 | X44: =Q44*Parametros!$B$13 -> 79230 | Y44: =Q44*Parametros!$B$7 -> 161500 | Z44: =Q44*Parametros!$B$8 -> 228000 | AA44: =Q44*Parametros!$B$9 -> 76000 | AB44: =Q44*P44 -> 132240
A45: EMP-044 | B45: Aguirre | C45: Julian | D45: M | E45: 33746 | F45: Soltero | G45: Bogotá D.C | H45: Bogotá | I45: AUXILIAR DE BODEGA | J45: 44562 | L45: COMPENSAR EPS | M45: PROTECCION | N45: ARL SURA | O45: COLSUBSIDIO | P45: 0.0435 | Q45: 1750905 | R45: =IF(Q45<=Parametros!$B$4,Parametros!$B$3,0) -> 249095 | S45: =Q45*Parametros!$B$5 -> 70036.2 | T45: =Q45*Parametros!$B$6 -> 70036.2 | U45: =(Q45+R45)*Parametros!$B$10 -> 166666.67 | V45: =U45*Parametros!$B$11 -> 20000 | W45: =(Q45+R45)*Parametros!$B$12 -> 166666.67 | X45: =Q45*Parametros!$B$13 -> 73012.739 | Y45: =Q45*Parametros!$B$7 -> 148826.92 | Z45: =Q45*Parametros!$B$8 -> 210108.6 | AA45: =Q45*Parametros!$B$9 -> 70036.2 | AB45: =Q45*P45 -> 76164.367
A46: EMP-045 | B46: Lopez | C46: Paula | D46: F | E46: 35759 | F46: Soltero | G46: Bogotá D.C | H46: Bogotá | I46: AUXILIAR DE BODEGA | J46: 45931 | L46: SANITAS | M46: COLPENSIONES | N46: ARL SURA | O46: COLSUBSIDIO | P46: 0.0435 | Q46: 1750905 | R46: =IF(Q46<=Parametros!$B$4,Parametros!$B$3,0) -> 249095 | S46: =Q46*Parametros!$B$5 -> 70036.2 | T46: =Q46*Parametros!$B$6 -> 70036.2 | U46: =(Q46+R46)*Parametros!$B$10 -> 166666.67 | V46: =U46*Parametros!$B$11 -> 20000 | W46: =(Q46+R46)*Parametros!$B$12 -> 166666.67 | X46: =Q46*Parametros!$B$13 -> 73012.739 | Y46: =Q46*Parametros!$B$7 -> 148826.92 | Z46: =Q46*Parametros!$B$8 -> 210108.6 | AA46: =Q46*Parametros!$B$9 -> 70036.2 | AB46: =Q46*P46 -> 76164.367
A47: EMP-046 | B47: Ospina | C47: Alejandro | D47: M | E47: 28044 | F47: Soltero | G47: Bogotá D.C | H47: Bogotá | I47: CONDUCTOR | J47: 45870 | L47: SURA EPS | M47: COLPENSIONES | N47: ARL SURA | O47: COLSUBSIDIO | P47: 0.0696 | Q47: 1900000 | R47: =IF(Q47<=Parametros!$B$4,Parametros!$B$3,0) -> 249095 | S47: =Q47*Parametros!$B$5 -> 76000 | T47: =Q47*Parametros!$B$6 -> 76000 | U47: =(Q47+R47)*Parametros!$B$10 -> 179091.25 | V47: =U47*Parametros!$B$11 -> 21490.95 | W47: =(Q47+R47)*Parametros!$B$12 -> 179091.25 | X47: =Q47*Parametros!$B$13 -> 79230 | Y47: =Q47*Parametros!$B$7 -> 161500 | Z47: =Q47*Parametros!$B$8 -> 228000 | AA47: =Q47*Parametros!$B$9 -> 76000 | AB47: =Q47*P47 -> 132240
A48: EMP-047 | B48: Duque | C48: Diana | D48: F | E48: 27442 | F48: Soltero | G48: Bogotá D.C | H48: Bogotá | I48: SUPERVISOR DE BODEGA | J48: 45400 | L48: FAMISANAR | M48: PORVENIR S.A. | N48: ARL SURA | O48: COLSUBSIDIO | P48: 0.0435 | Q48: 2600000 | R48: =IF(Q48<=Parametros!$B$4,Parametros!$B$3,0) -> 249095 | S48: =Q48*Parametros!$B$5 -> 104000 | T48: =Q48*Parametros!$B$6 -> 104000 | U48: =(Q48+R48)*Parametros!$B$10 -> 237424.58 | V48: =U48*Parametros!$B$11 -> 28490.95 | W48: =(Q48+R48)*Parametros!$B$12 -> 237424.58 | X48: =Q48*Parametros!$B$13 -> 108420 | Y48: =Q48*Parametros!$B$7 -> 221000 | Z48: =Q48*Parametros!$B$8 -> 312000 | AA48: =Q48*Parametros!$B$9 -> 104000 | AB48: =Q48*P48 -> 113100
A49: EMP-048 | B49: Mendoza | C49: David | D49: M | E49: 33589 | F49: Soltero | G49: Bogotá D.C | H49: Bogotá | I49: AUXILIAR ADMINISTRATIVO | J49: 45413 | L49: SANITAS | M49: COLPENSIONES | N49: ARL SURA | O49: COLSUBSIDIO | P49: 0.00522 | Q49: 1750905 | R49: =IF(Q49<=Parametros!$B$4,Parametros!$B$3,0) -> 249095 | S49: =Q49*Parametros!$B$5 -> 70036.2 | T49: =Q49*Parametros!$B$6 -> 70036.2 | U49: =(Q49+R49)*Parametros!$B$10 -> 166666.67 | V49: =U49*Parametros!$B$11 -> 20000 | W49: =(Q49+R49)*Parametros!$B$12 -> 166666.67 | X49: =Q49*Parametros!$B$13 -> 73012.739 | Y49: =Q49*Parametros!$B$7 -> 148826.92 | Z49: =Q49*Parametros!$B$8 -> 210108.6 | AA49: =Q49*Parametros!$B$9 -> 70036.2 | AB49: =Q49*P49 -> 9139.7241
A50: EMP-049 | B50: Mendoza | C50: Claudia | D50: F | E50: 33960 | F50: Soltero | G50: Bogotá D.C | H50: Bogotá | I50: ANALISTA DE RUTAS | J50: 46230 | L50: SALUD TOTAL | M50: PORVENIR S.A. | N50: ARL SURA | O50: COLSUBSIDIO | P50: 0.00522 | Q50: 1750905 | R50: =IF(Q50<=Parametros!$B$4,Parametros!$B$3,0) -> 249095 | S50: =Q50*Parametros!$B$5 -> 70036.2 | T50: =Q50*Parametros!$B$6 -> 70036.2 | U50: =(Q50+R50)*Parametros!$B$10 -> 166666.67 | V50: =U50*Parametros!$B$11 -> 20000 | W50: =(Q50+R50)*Parametros!$B$12 -> 166666.67 | X50: =Q50*Parametros!$B$13 -> 73012.739 | Y50: =Q50*Parametros!$B$7 -> 148826.92 | Z50: =Q50*Parametros!$B$8 -> 210108.6 | AA50: =Q50*Parametros!$B$9 -> 70036.2 | AB50: =Q50*P50 -> 9139.7241
A51: EMP-050 | B51: Mendoza | C51: Alejandro | D51: M | E51: 32071 | F51: Soltero | G51: Bogotá D.C | H51: Bogotá | I51: AUXILIAR DE BODEGA | J51: 46027 | L51: FAMISANAR | M51: PROTECCION | N51: ARL SURA | O51: COLSUBSIDIO | P51: 0.0435 | Q51: 1750905 | R51: =IF(Q51<=Parametros!$B$4,Parametros!$B$3,0) -> 249095 | S51: =Q51*Parametros!$B$5 -> 70036.2 | T51: =Q51*Parametros!$B$6 -> 70036.2 | U51: =(Q51+R51)*Parametros!$B$10 -> 166666.67 | V51: =U51*Parametros!$B$11 -> 20000 | W51: =(Q51+R51)*Parametros!$B$12 -> 166666.67 | X51: =Q51*Parametros!$B$13 -> 73012.739 | Y51: =Q51*Parametros!$B$7 -> 148826.92 | Z51: =Q51*Parametros!$B$8 -> 210108.6 | AA51: =Q51*Parametros!$B$9 -> 70036.2 | AB51: =Q51*P51 -> 76164.367
A52: EMP-051 | B52: Mendoza | C52: Fernando | D52: M | E52: 28584 | F52: Soltero | G52: Cundinamarca | H52: SOACHA | I52: AUXILIAR CONTABLE | J52: 43497 | L52: SANITAS | M52: PORVENIR S.A. | N52: ARL SURA | O52: COLSUBSIDIO | P52: 0.00522 | Q52: 1750905 | R52: =IF(Q52<=Parametros!$B$4,Parametros!$B$3,0) -> 249095 | S52: =Q52*Parametros!$B$5 -> 70036.2 | T52: =Q52*Parametros!$B$6 -> 70036.2 | U52: =(Q52+R52)*Parametros!$B$10 -> 166666.67 | V52: =U52*Parametros!$B$11 -> 20000 | W52: =(Q52+R52)*Parametros!$B$12 -> 166666.67 | X52: =Q52*Parametros!$B$13 -> 73012.739 | Y52: =Q52*Parametros!$B$7 -> 148826.92 | Z52: =Q52*Parametros!$B$8 -> 210108.6 | AA52: =Q52*Parametros!$B$9 -> 70036.2 | AB52: =Q52*P52 -> 9139.7241
A53: EMP-052 | B53: Perez | C53: Gustavo | D53: M | E53: 27695 | F53: Soltero | G53: Cundinamarca | H53: SOACHA | I53: ANALISTA DE INVENTARIOS | J53: 45794 | L53: FAMISANAR | M53: PORVENIR S.A. | N53: ARL SURA | O53: COLSUBSIDIO | P53: 0.00522 | Q53: 1750905 | R53: =IF(Q53<=Parametros!$B$4,Parametros!$B$3,0) -> 249095 | S53: =Q53*Parametros!$B$5 -> 70036.2 | T53: =Q53*Parametros!$B$6 -> 70036.2 | U53: =(Q53+R53)*Parametros!$B$10 -> 166666.67 | V53: =U53*Parametros!$B$11 -> 20000 | W53: =(Q53+R53)*Parametros!$B$12 -> 166666.67 | X53: =Q53*Parametros!$B$13 -> 73012.739 | Y53: =Q53*Parametros!$B$7 -> 148826.92 | Z53: =Q53*Parametros!$B$8 -> 210108.6 | AA53: =Q53*Parametros!$B$9 -> 70036.2 | AB53: =Q53*P53 -> 9139.7241
A54: EMP-053 | B54: Pineda | C54: Miguel | D54: M | E54: 30609 | F54: Soltero | G54: Cundinamarca | H54: SOACHA | I54: CONDUCTOR | J54: 44959 | K54: 46054 | L54: SALUD TOTAL | M54: PORVENIR S.A. | N54: ARL SURA | O54: COLSUBSIDIO | P54: 0.0696 | Q54: 1900000 | R54: =IF(Q54<=Parametros!$B$4,Parametros!$B$3,0) -> 249095 | S54: =Q54*Parametros!$B$5 -> 76000 | T54: =Q54*Parametros!$B$6 -> 76000 | U54: =(Q54+R54)*Parametros!$B$10 -> 179091.25 | V54: =U54*Parametros!$B$11 -> 21490.95 | W54: =(Q54+R54)*Parametros!$B$12 -> 179091.25 | X54: =Q54*Parametros!$B$13 -> 79230 | Y54: =Q54*Parametros!$B$7 -> 161500 | Z54: =Q54*Parametros!$B$8 -> 228000 | AA54: =Q54*Parametros!$B$9 -> 76000 | AB54: =Q54*P54 -> 132240
A55: EMP-054 | B55: Mendoza | C55: Luis | D55: M | E55: 32446 | F55: Soltero | G55: Bogotá D.C | H55: Bogotá | I55: AUXILIAR DE NOMINA | J55: 45352 | L55: FAMISANAR | M55: COLFONDOS | N55: ARL SURA | O55: COLSUBSIDIO | P55: 0.00522 | Q55: 1750905 | R55: =IF(Q55<=Parametros!$B$4,Parametros!$B$3,0) -> 249095 | S55: =Q55*Parametros!$B$5 -> 70036.2 | T55: =Q55*Parametros!$B$6 -> 70036.2 | U55: =(Q55+R55)*Parametros!$B$10 -> 166666.67 | V55: =U55*Parametros!$B$11 -> 20000 | W55: =(Q55+R55)*Parametros!$B$12 -> 166666.67 | X55: =Q55*Parametros!$B$13 -> 73012.739 | Y55: =Q55*Parametros!$B$7 -> 148826.92 | Z55: =Q55*Parametros!$B$8 -> 210108.6 | AA55: =Q55*Parametros!$B$9 -> 70036.2 | AB55: =Q55*P55 -> 9139.7241
A56: EMP-055 | B56: Lopez | C56: David | D56: M | E56: 29479 | F56: Soltero | G56: Bogotá D.C | H56: Bogotá | I56: ANALISTA DE COSTOS | J56: 44380 | L56: COMPENSAR EPS | M56: PORVENIR S.A. | N56: ARL SURA | O56: COLSUBSIDIO | P56: 0.00522 | Q56: 1750905 | R56: =IF(Q56<=Parametros!$B$4,Parametros!$B$3,0) -> 249095 | S56: =Q56*Parametros!$B$5 -> 70036.2 | T56: =Q56*Parametros!$B$6 -> 70036.2 | U56: =(Q56+R56)*Parametros!$B$10 -> 166666.67 | V56: =U56*Parametros!$B$11 -> 20000 | W56: =(Q56+R56)*Parametros!$B$12 -> 166666.67 | X56: =Q56*Parametros!$B$13 -> 73012.739 | Y56: =Q56*Parametros!$B$7 -> 148826.92 | Z56: =Q56*Parametros!$B$8 -> 210108.6 | AA56: =Q56*Parametros!$B$9 -> 70036.2 | AB56: =Q56*P56 -> 9139.7241
A57: EMP-056 | B57: Castro | C57: David | D57: M | E57: 30423 | F57: Soltero | G57: Bogotá D.C | H57: Bogotá | I57: AUXILIAR ADMINISTRATIVO | J57: 45323 | L57: SALUD TOTAL | M57: PORVENIR S.A. | N57: ARL SURA | O57: COLSUBSIDIO | P57: 0.00522 | Q57: 1750905 | R57: =IF(Q57<=Parametros!$B$4,Parametros!$B$3,0) -> 249095 | S57: =Q57*Parametros!$B$5 -> 70036.2 | T57: =Q57*Parametros!$B$6 -> 70036.2 | U57: =(Q57+R57)*Parametros!$B$10 -> 166666.67 | V57: =U57*Parametros!$B$11 -> 20000 | W57: =(Q57+R57)*Parametros!$B$12 -> 166666.67 | X57: =Q57*Parametros!$B$13 -> 73012.739 | Y57: =Q57*Parametros!$B$7 -> 148826.92 | Z57: =Q57*Parametros!$B$8 -> 210108.6 | AA57: =Q57*Parametros!$B$9 -> 70036.2 | AB57: =Q57*P57 -> 9139.7241
A58: EMP-057 | B58: Gonzalez | C58: Ivan | D58: M | E58: 26456 | F58: Soltero | G58: Bogotá D.C | H58: Bogotá | I58: DIRECTOR COMERCIAL | J58: 44623 | L58: COMPENSAR EPS | M58: COLPENSIONES | N58: ARL SURA | O58: COLSUBSIDIO | P58: 0.00522 | Q58: 6500000 | R58: =IF(Q58<=Parametros!$B$4,Parametros!$B$3,0) -> 0 | S58: =Q58*Parametros!$B$5 -> 260000 | T58: =Q58*Parametros!$B$6 -> 260000 | U58: =(Q58+R58)*Parametros!$B$10 -> 541666.67 | V58: =U58*Parametros!$B$11 -> 65000 | W58: =(Q58+R58)*Parametros!$B$12 -> 541666.67 | X58: =Q58*Parametros!$B$13 -> 271050 | Y58: =Q58*Parametros!$B$7 -> 552500 | Z58: =Q58*Parametros!$B$8 -> 780000 | AA58: =Q58*Parametros!$B$9 -> 260000 | AB58: =Q58*P58 -> 33930
A59: EMP-058 | B59: Ortiz | C59: Diego | D59: M | E59: 28481 | F59: Soltero | G59: Bogotá D.C | H59: Bogotá | I59: ASESOR COMERCIAL | J59: 45383 | L59: FAMISANAR | M59: COLPENSIONES | N59: ARL SURA | O59: COLSUBSIDIO | P59: 0.00522 | Q59: 2000000 | R59: =IF(Q59<=Parametros!$B$4,Parametros!$B$3,0) -> 249095 | S59: =Q59*Parametros!$B$5 -> 80000 | T59: =Q59*Parametros!$B$6 -> 80000 | U59: =(Q59+R59)*Parametros!$B$10 -> 187424.58 | V59: =U59*Parametros!$B$11 -> 22490.95 | W59: =(Q59+R59)*Parametros!$B$12 -> 187424.58 | X59: =Q59*Parametros!$B$13 -> 83400 | Y59: =Q59*Parametros!$B$7 -> 170000 | Z59: =Q59*Parametros!$B$8 -> 240000 | AA59: =Q59*Parametros!$B$9 -> 80000 | AB59: =Q59*P59 -> 10440
...
